============================= test session starts ==============================
platform linux -- Python 3.6.6, pytest-3.6.0, py-1.7.0, pluggy-0.6.0 -- /usr/bin/python3
cachedir: .pytest_cache
driver: Remote
sensitiveurl: .*
metadata: {'Python': '3.6.6', 'Platform': 'Linux-4.19.76-linuxkit-x86_64-with-Ubuntu-18.04-bionic', 'Packages': {'pytest': '3.6.0', 'py': '1.7.0', 'pluggy': '0.6.0'}, 'Plugins': {'xdist': '1.22.2', 'variables': '1.7.1', 'test-groups': '1.0.3', 'selenium': '1.13.0', 'rerunfailures': '4.1', 'repeat': '0.4.1', 'metadata': '1.7.0', 'html': '1.19.0', 'forked': '0.2', 'base-url': '1.4.1'}, 'Base URL': '', 'Driver': 'Remote', 'Capabilities': {'browserName': 'firefox'}, 'Server': 'selenium-hub:4444'}
rootdir: /opt/work, inifile: pytest.ini
plugins: xdist-1.22.2, variables-1.7.1, test-groups-1.0.3, selenium-1.13.0, rerunfailures-4.1, repeat-0.4.1, metadata-1.7.0, html-1.19.0, forked-0.2, base-url-1.4.1
collecting ... collected 9 items / 5 deselected

t/test_front_page_search.py::TestFrontPageSearch::test_search_1 FAILED   [ 25%]
t/test_front_page_search.py::TestFrontPageSearch::test_search_2 FAILED   [ 50%]
t/test_front_page_search.py::TestFrontPageSearch::test_search_3 FAILED   [ 75%]
t/test_front_page_search.py::TestFrontPageSearch::test_search_4 FAILED   [100%]

=================================== FAILURES ===================================
______________________ TestFrontPageSearch.test_search_1 _______________________
/usr/local/lib/python3.6/dist-packages/selene/wait.py:13: in wait_for
    return condition.fn(entity)
/usr/local/lib/python3.6/dist-packages/selene/conditions.py:141: in fn
    return self.match(element.get_actual_webelement())
/usr/local/lib/python3.6/dist-packages/selene/elements.py:205: in get_actual_webelement
    return self.__delegate__
/usr/local/lib/python3.6/dist-packages/selene/elements.py:200: in __delegate__
    return self._locator.find()
/usr/local/lib/python3.6/dist-packages/selene/elements.py:45: in find
    return self._search_context.find_element(*self._by)
/usr/local/lib/python3.6/dist-packages/selene/driver.py:89: in find_element
    return self._webdriver.find_element(by, value)
/usr/local/lib/python3.6/dist-packages/selenium/webdriver/remote/webdriver.py:955: in find_element
    'value': value})['value']
/usr/local/lib/python3.6/dist-packages/selenium/webdriver/remote/webdriver.py:312: in execute
    self.error_handler.check_response(response)
/usr/local/lib/python3.6/dist-packages/selenium/webdriver/remote/errorhandler.py:242: in check_response
    raise exception_class(message, screen, stacktrace)
E   selenium.common.exceptions.NoSuchElementException: Message: Unable to locate element: #resultStats

During handling of the above exception, another exception occurred:
/usr/local/lib/python3.6/dist-packages/selene/elements.py:188: in _wait_with_screenshot
    return wait_for(entity, condition, timeout, polling)
/usr/local/lib/python3.6/dist-packages/selene/wait.py:35: in wait_for
    reason=reason_string), screen, stacktrace)
E   selenium.common.exceptions.TimeoutException: Message: 
E               failed while waiting 4 seconds
E               to assert Visible
E               for first_by('css selector', '#resultStats')
E   
E               reason: NoSuchElementException: Unable to locate element: #resultStats

During handling of the above exception, another exception occurred:
t/test_front_page_search.py:41: in test_search_1
    .should(be.visible)
/usr/local/lib/python3.6/dist-packages/selene/elements.py:306: in should
    _wait_with_screenshot(self._webdriver, self, condition, timeout)
/usr/local/lib/python3.6/dist-packages/selene/elements.py:193: in _wait_with_screenshot
    raise TimeoutException(msg, e.screen, e.stacktrace)
E   selenium.common.exceptions.TimeoutException: Message: 
E               failed while waiting 4 seconds
E               to assert Visible
E               for first_by('css selector', '#resultStats')
E   
E               reason: NoSuchElementException: Unable to locate element: #resultStats
E               screenshot: file:///opt/work/screen_1592082017309.png
------------------------------- pytest-selenium --------------------------------
URL: https://www.google.com/search?source=hp&ei=az7lXpiGBZWMtAa0h4DABg&q=cheese&oq=cheese&gs_lcp=CgZwc3ktYWIQDDIFCAAQsQMyBQgAELEDMgUIABCxAzIFCAAQsQMyAggAMgIIADICCAAyBQgAELEDMgUIABCxAzIFCAAQsQM6BQgAEIMBUM8EWIsFYKAHaABwAHgBgAHeAYgBngWSAQUwLjMuMZgBAKABAaoBB2d3cy13aXo&sclient=psy-ab&ved=0ahUKEwjY57Xd1__pAhUVBs0KHbQDAGgQ4dUDCAg
______________________ TestFrontPageSearch.test_search_2 _______________________
/usr/local/lib/python3.6/dist-packages/selene/wait.py:13: in wait_for
    return condition.fn(entity)
/usr/local/lib/python3.6/dist-packages/selene/conditions.py:141: in fn
    return self.match(element.get_actual_webelement())
/usr/local/lib/python3.6/dist-packages/selene/elements.py:205: in get_actual_webelement
    return self.__delegate__
/usr/local/lib/python3.6/dist-packages/selene/elements.py:200: in __delegate__
    return self._locator.find()
/usr/local/lib/python3.6/dist-packages/selene/elements.py:45: in find
    return self._search_context.find_element(*self._by)
/usr/local/lib/python3.6/dist-packages/selene/driver.py:89: in find_element
    return self._webdriver.find_element(by, value)
/usr/local/lib/python3.6/dist-packages/selenium/webdriver/remote/webdriver.py:955: in find_element
    'value': value})['value']
/usr/local/lib/python3.6/dist-packages/selenium/webdriver/remote/webdriver.py:312: in execute
    self.error_handler.check_response(response)
/usr/local/lib/python3.6/dist-packages/selenium/webdriver/remote/errorhandler.py:242: in check_response
    raise exception_class(message, screen, stacktrace)
E   selenium.common.exceptions.NoSuchElementException: Message: Unable to locate element: #resultStats

During handling of the above exception, another exception occurred:
/usr/local/lib/python3.6/dist-packages/selene/elements.py:188: in _wait_with_screenshot
    return wait_for(entity, condition, timeout, polling)
/usr/local/lib/python3.6/dist-packages/selene/wait.py:35: in wait_for
    reason=reason_string), screen, stacktrace)
E   selenium.common.exceptions.TimeoutException: Message: 
E               failed while waiting 4 seconds
E               to assert Visible
E               for first_by('css selector', '#resultStats')
E   
E               reason: NoSuchElementException: Unable to locate element: #resultStats

During handling of the above exception, another exception occurred:
t/test_front_page_search.py:58: in test_search_2
    .should(be.visible)
/usr/local/lib/python3.6/dist-packages/selene/elements.py:306: in should
    _wait_with_screenshot(self._webdriver, self, condition, timeout)
/usr/local/lib/python3.6/dist-packages/selene/elements.py:193: in _wait_with_screenshot
    raise TimeoutException(msg, e.screen, e.stacktrace)
E   selenium.common.exceptions.TimeoutException: Message: 
E               failed while waiting 4 seconds
E               to assert Visible
E               for first_by('css selector', '#resultStats')
E   
E               reason: NoSuchElementException: Unable to locate element: #resultStats
E               screenshot: file:///opt/work/screen_1592082017310.png
------------------------------- pytest-selenium --------------------------------
URL: https://www.google.com/search?source=hp&ei=fD7lXpLUOZr5tAbOsYjwAQ&q=cheese&oq=cheese&gs_lcp=CgZwc3ktYWIQDDIFCAAQsQMyBQgAELEDMgUIABCxAzIFCAAQsQMyAggAMgIIADICCAAyBQgAELEDMgIIADIFCAAQsQNQvAZYngdgzghoAHAAeACAAWuIAWuSAQMwLjGYAQCgAQGqAQdnd3Mtd2l6&sclient=psy-ab&ved=0ahUKEwiSgvjl1__pAhWaPM0KHc4YAh4Q4dUDCAg
______________________ TestFrontPageSearch.test_search_3 _______________________
/usr/local/lib/python3.6/dist-packages/selene/wait.py:13: in wait_for
    return condition.fn(entity)
/usr/local/lib/python3.6/dist-packages/selene/conditions.py:141: in fn
    return self.match(element.get_actual_webelement())
/usr/local/lib/python3.6/dist-packages/selene/elements.py:205: in get_actual_webelement
    return self.__delegate__
/usr/local/lib/python3.6/dist-packages/selene/elements.py:200: in __delegate__
    return self._locator.find()
/usr/local/lib/python3.6/dist-packages/selene/elements.py:45: in find
    return self._search_context.find_element(*self._by)
/usr/local/lib/python3.6/dist-packages/selene/driver.py:89: in find_element
    return self._webdriver.find_element(by, value)
/usr/local/lib/python3.6/dist-packages/selenium/webdriver/remote/webdriver.py:955: in find_element
    'value': value})['value']
/usr/local/lib/python3.6/dist-packages/selenium/webdriver/remote/webdriver.py:312: in execute
    self.error_handler.check_response(response)
/usr/local/lib/python3.6/dist-packages/selenium/webdriver/remote/errorhandler.py:242: in check_response
    raise exception_class(message, screen, stacktrace)
E   selenium.common.exceptions.NoSuchElementException: Message: Unable to locate element: #resultStats

During handling of the above exception, another exception occurred:
/usr/local/lib/python3.6/dist-packages/selene/elements.py:188: in _wait_with_screenshot
    return wait_for(entity, condition, timeout, polling)
/usr/local/lib/python3.6/dist-packages/selene/wait.py:35: in wait_for
    reason=reason_string), screen, stacktrace)
E   selenium.common.exceptions.TimeoutException: Message: 
E               failed while waiting 4 seconds
E               to assert Visible
E               for first_by('css selector', '#resultStats')
E   
E               reason: NoSuchElementException: Unable to locate element: #resultStats

During handling of the above exception, another exception occurred:
t/test_front_page_search.py:72: in test_search_3
    .result_stats.should(be.visible)
/usr/local/lib/python3.6/dist-packages/selene/elements.py:306: in should
    _wait_with_screenshot(self._webdriver, self, condition, timeout)
/usr/local/lib/python3.6/dist-packages/selene/elements.py:193: in _wait_with_screenshot
    raise TimeoutException(msg, e.screen, e.stacktrace)
E   selenium.common.exceptions.TimeoutException: Message: 
E               failed while waiting 4 seconds
E               to assert Visible
E               for first_by('css selector', '#resultStats')
E   
E               reason: NoSuchElementException: Unable to locate element: #resultStats
E               screenshot: file:///opt/work/screen_1592082017311.png
------------------------------- pytest-selenium --------------------------------
URL: https://www.google.com/search?source=hp&ei=kD7lXqUKzqy1Bp-Im4gC&q=cheese&oq=cheese&gs_lcp=CgZwc3ktYWIQDDIFCAAQsQMyBQgAELEDMgUIABCxAzIFCAAQsQMyAggAMgIIADICCAAyBQgAELEDMgUIABCxAzIFCAAQsQM6BQgAEIMBUIwCWMsCYIMFaABwAHgCgAGYAogBxwaSAQUwLjEuM5gBAKABAaoBB2d3cy13aXo&sclient=psy-ab&ved=0ahUKEwilkoPv1__pAhVOVs0KHR_EBiEQ4dUDCAg
______________________ TestFrontPageSearch.test_search_4 _______________________
/usr/local/lib/python3.6/dist-packages/selene/wait.py:13: in wait_for
    return condition.fn(entity)
/usr/local/lib/python3.6/dist-packages/selene/conditions.py:141: in fn
    return self.match(element.get_actual_webelement())
/usr/local/lib/python3.6/dist-packages/selene/elements.py:205: in get_actual_webelement
    return self.__delegate__
/usr/local/lib/python3.6/dist-packages/selene/elements.py:200: in __delegate__
    return self._locator.find()
/usr/local/lib/python3.6/dist-packages/selene/elements.py:45: in find
    return self._search_context.find_element(*self._by)
/usr/local/lib/python3.6/dist-packages/selene/driver.py:89: in find_element
    return self._webdriver.find_element(by, value)
/usr/local/lib/python3.6/dist-packages/selenium/webdriver/remote/webdriver.py:955: in find_element
    'value': value})['value']
/usr/local/lib/python3.6/dist-packages/selenium/webdriver/remote/webdriver.py:312: in execute
    self.error_handler.check_response(response)
/usr/local/lib/python3.6/dist-packages/selenium/webdriver/remote/errorhandler.py:242: in check_response
    raise exception_class(message, screen, stacktrace)
E   selenium.common.exceptions.NoSuchElementException: Message: Unable to locate element: #resultStats

During handling of the above exception, another exception occurred:
/usr/local/lib/python3.6/dist-packages/selene/elements.py:188: in _wait_with_screenshot
    return wait_for(entity, condition, timeout, polling)
/usr/local/lib/python3.6/dist-packages/selene/wait.py:35: in wait_for
    reason=reason_string), screen, stacktrace)
E   selenium.common.exceptions.TimeoutException: Message: 
E               failed while waiting 4 seconds
E               to assert Visible
E               for first_by('css selector', '#resultStats')
E   
E               reason: NoSuchElementException: Unable to locate element: #resultStats

During handling of the above exception, another exception occurred:
t/test_front_page_search.py:86: in test_search_4
    .result_stats.should(be.visible)
/usr/local/lib/python3.6/dist-packages/selene/elements.py:306: in should
    _wait_with_screenshot(self._webdriver, self, condition, timeout)
/usr/local/lib/python3.6/dist-packages/selene/elements.py:193: in _wait_with_screenshot
    raise TimeoutException(msg, e.screen, e.stacktrace)
E   selenium.common.exceptions.TimeoutException: Message: 
E               failed while waiting 4 seconds
E               to assert Visible
E               for first_by('css selector', '#resultStats')
E   
E               reason: NoSuchElementException: Unable to locate element: #resultStats
E               screenshot: file:///opt/work/screen_1592082017312.png
------------------------------- pytest-selenium --------------------------------
URL: https://www.google.com/search?source=hp&ei=oj7lXs-MGtWE9PwPl5u2mAs&q=cheese&oq=cheese&gs_lcp=CgZwc3ktYWIQDDIFCAAQsQMyBQgAELEDMgUIABCxAzIFCAAQsQMyAggAMgIIADICCAAyBQgAELEDMgUIABCxAzIFCAAQsQM6BQgAEIMBUKYEWKMFYO8GaABwAHgBgAG_AYgB8gSSAQMwLjSYAQCgAQGqAQdnd3Mtd2l6&sclient=psy-ab&ved=0ahUKEwjP5ef31__pAhVVAp0JHZeNDbMQ4dUDCAg
------------------- generated xml file: /opt/work/result.xml -------------------
=================== 4 failed, 5 deselected in 74.69 seconds ====================
